Workbook

Sheet Executive Summary

Sheet Historical & Assumptions
A1: DOLLARAMA INC. | HISTORICAL & ASSUMPTIONS CAD in millions | FY2023A–FY2030E
A3: Fiscal Year | B3: FY2023A | C3: FY2024A | D3: FY2025A | E3: FY2026A | F3: FY2027E | G3: FY2028E | H3: FY2029E | I3: FY2030E
A4: Revenue | B4: 5052.741 | C4: 5867.348 | D4: 6413.145 | E4: 7255.754 | F4: {='Operating Model'!F4:F5} -> 8029.9896 | G4: {='Operating Model'!G4:G5} -> 8563.4889 | H4: {='Operating Model'!H4:H5} -> 9113.8441 | I4: {='Operating Model'!I4:I5} -> 9672.3099
A5: Revenue Growth % | B5: 0.167 | C5: =(C4/B4)-1 -> 0.16122081 | D5: =(D4/C4)-1 -> 0.093022776 | E5: =(E4/D4)-1 -> 0.1313878 | F5: 0.10670643 | G5: 0.066438358 | H5: 0.064267634 | I5: 0.061276647
A6: COGS | B6: 2854.535 | C6: 3253.907 | D6: 3519.399 | E6: 3987.089 | F6: ='Operating Model'!F6 -> 4488.7642 | G6: ='Operating Model'!G6 -> 4769.8633 | H6: ='Operating Model'!H6 -> 5058.1835 | I6: ='Operating Model'!I6 -> 5348.7874
A7: Gross Profit | B7: 2198.206 | C7: 2613.441 | D7: 2893.746 | E7: 3268.665 | F7: ='Operating Model'!F7 -> 3541.2254 | G7: ='Operating Model'!G7 -> 3793.6256 | H7: ='Operating Model'!H7 -> 4055.6606 | I7: ='Operating Model'!I7 -> 4323.5225
A8: Gross Margin % | B8: =B7/B4 -> 0.43505218 | C8: =C7/C4 -> 0.44542117 | D8: =D7/D4 -> 0.45122105 | E8: =E7/E4 -> 0.45049281 | F8: ='Operating Model'!F8 -> 0.441 | G8: ='Operating Model'!G8 -> 0.443 | H8: ='Operating Model'!H8 -> 0.445 | I8: ='Operating Model'!I8 -> 0.447
A9: SG&A | B9: 720.312 | C9: 844.871 | D9: 930.168 | E9: 1093.289 | F9: ='Operating Model'!F9 -> 1204.4984 | G9: ='Operating Model'!G9 -> 1275.9598 | H9: ='Operating Model'!H9 -> 1348.8489 | I9: ='Operating Model'!I9 -> 1421.8296
A10: SG&A % of Revenue | B10: =B9/B4 -> 0.14255866 | C10: =C9/C4 -> 0.14399538 | D10: =D9/D4 -> 0.14504085 | E10: =E9/E4 -> 0.1506789 | F10: ='Operating Model'!F10 -> 0.15 | G10: ='Operating Model'!G10 -> 0.149 | H10: ='Operating Model'!H10 -> 0.148 | I10: ='Operating Model'!I10 -> 0.147
A11: D&A | B11: 331.792 | C11: 348.142 | D11: 382.805 | E11: 429.053 | F11: {='Operating Model'!F13:F14} -> 489.47748 | G11: {='Operating Model'!G13:G14} -> 521.99756 | H11: {='Operating Model'!H13:H14} -> 555.54511 | I11: {='Operating Model'!I13:I14} -> 589.58705
A12: D&A % of Revenue | B12: =B11/B4 -> 0.065665745 | C12: =C11/C4 -> 0.059335495 | D12: =D11/D4 -> 0.059690682 | E12: =E11/E4 -> 0.059132793 | F12: 0.060956179 | G12: 0.060956179 | H12: 0.060956179 | I12: 0.060956179
A13: EBITDA | B13: 1477.894 | C13: 1768.57 | D13: 1963.578 | E13: 2175.376 | F13: {='Operating Model'!F11:F12} -> 2336.727 | G13: {='Operating Model'!G11:G12} -> 2517.6657 | H13: {='Operating Model'!H11:H12} -> 2706.8117 | I13: {='Operating Model'!I11:I12} -> 2901.693
A14: EBITDA Margin % | B14: =B13/B4 -> 0.29249352 | C14: =C13/C4 -> 0.30142579 | D14: =D13/D4 -> 0.3061802 | E14: =E13/E4 -> 0.29981391 | F14: 0.291 | G14: 0.294 | H14: 0.297 | I14: 0.3
A15: Operating Income (EBIT) | B15: ='Operating Model'!B15 -> 1146.102 | C15: ='Operating Model'!C15 -> 1420.428 | D15: ='Operating Model'!D15 -> 1580.773 | E15: ='Operating Model'!E15 -> 1746.323 | F15: {='Operating Model'!F15:F16} -> 1847.2495 | G15: {='Operating Model'!G15:G16} -> 1995.6682 | H15: {='Operating Model'!H15:H16} -> 2151.2666 | I15: {='Operating Model'!I15:I16} -> 2312.1059
A16: Operating Margin % | B16: =B15/B4 -> 0.22682778 | C16: =C15/C4 -> 0.24209029 | D16: =D15/D4 -> 0.24648951 | E16: =E15/E4 -> 0.24068112 | F16: 0.232 | G16: 0.235 | H16: 0.238 | I16: 0.241
A17: Net Financing Costs | B17: 115.394 | C17: 144.842 | D17: 163.782 | E17: 184.02 | F17: ='Working Capital & Financing'!F23 -> 193.221 | G17: ='Working Capital & Financing'!G23 -> 202.88205 | H17: ='Working Capital & Financing'!H23 -> 213.02615 | I17: ='Working Capital & Financing'!I23 -> 223.67746
A19: Metric | B19: FY2023A | C19: FY2024A | D19: FY2025A | E19: FY2026A
A20: Revenue | B20: 5052.741 | C20: 5867.348 | D20: 6413.145 | E20: 7255.754
A21: COGS | B21: 2854.535 | C21: 3253.907 | D21: 3519.399 | E21: 3987.089
A22: SG&A | B22: 720.312 | C22: 844.871 | D22: 930.168 | E22: 1093.289
A23: D&A | B23: 331.792 | C23: 348.142 | D23: 382.805 | E23: 429.053
A24: Net Financing Costs | B24: 115.394 | C24: 144.842 | D24: 163.782 | E24: 184.02
A25: Income taxes | B25: 274.244 | C25: 340.419 | D25: 378.351 | E25: 454.749
A26: Cash | B26: 101.261 | C26: 313.915 | D26: 122.685 | E26: 331.569
A27: Accounts receivable | B27: 56.29 | C27: 32.474 | D27: 46.638 | E27: 38.5
A28: Inventory | B28: 957.172 | C28: 916.812 | D28: 921.095 | E28: 1103.175
A29: Accounts payable & accruals | B29: 336.862 | C29: 334.357 | D29: 354.9 | E29: 461.766
A30: PP&E | B30: 802.75 | C30: 950.994 | D30: 1046.39 | E30: 1258.499
A31: PP&E Depreciation | B31: 92.956 | C31: 103.923 | D31: 116.238 | E31: 104.806
... A46: Dividends paid | B46: 62.975 | C46: 76.131 | D46: 97.244 | E46: 113.196

Sheet Operating Drivers
A1: DOLLARAMA INC. | Operating Drivers CAD in millions | FY2023A–FY2030E
A3: CANADA STORE NETWORK | B3: FY2023A | C3: FY2024A | D3: FY2025A | E3: FY2026A | F3: FY2027E | G3: FY2028E | H3: FY2029E | I3: FY2030E
A4: Ending Store Count | B4: 1486 | C4: =B4+C5 -> 1551 | D4: =C4+D5 -> 1616 | E4: =D4+E5 -> 1691 | F4: =E4+F5 -> 1761 | G4: =F4+G5 -> 1831 | H4: =G4+H5 -> 1901 | I4: =H4+I5 -> 1966
A5: Net New Stores | B5: 65 | C5: 65 | D5: 65 | E5: 75 | F5: 70 | G5: 70 | H5: 70 | I5: 65
A6: Store Growth % | B6: =(B4/1421)-1 -> 0.045742435 | C6: =(C4/B4)-1 -> 0.043741588 | D6: =(D4/C4)-1 -> 0.041908446 | E6: =(E4/D4)-1 -> 0.046410891 | F6: =(F4/E4)-1 -> 0.041395624 | G6: =(G4/F4)-1 -> 0.039750142 | H6: =(H4/G4)-1 -> 0.038230475 | I6: =(I4/H4)-1 -> 0.03419253
A8: Province / Territory | B8: FY2023A | C8: FY2024A | D8: FY2025A | E8: FY2026A | F8: FY2027E | G8: FY2028E | H8: FY2029E | I8: FY2030E
A9: Alberta | B9: 154 | C9: 168 | D9: 183 | E9: 204 | F9: 213 | G9: 221 | H9: 229 | I9: 237
A10: British Columbia | B10: 132 | C10: 137 | D10: 148 | E10: 156 | F10: 163 | G10: 169 | H10: 175 | I10: 181
A11: Manitoba | B11: 47 | C11: 55 | D11: 58 | E11: 58 | F11: 60 | G11: 63 | H11: 65 | I11: 67
A12: New Brunswick | B12: 44 | C12: 47 | D12: 47 | E12: 48 | F12: 50 | G12: 52 | H12: 54 | I12: 56
A13: Newfoundland and Labrador | B13: 26 | C13: 27 | D13: 27 | E13: 29 | F13: 30 | G13: 31 | H13: 33 | I13: 34
A14: Northwest Territories | B14: 1 | C14: 1 | D14: 1 | E14: 1 | F14: 1 | G14: 1 | H14: 1 | I14: 1
A15: Nova Scotia | B15: 43 | C15: 43 | D15: 45 | E15: 46 | F15: 48 | G15: 50 | H15: 52 | I15: 54
A16: Ontario | B16: 590 | C16: 612 | D16: 630 | E16: 656 | F16: 683 | G16: 710 | H16: 738 | I16: 763
A17: Prince Edward Island | B17: 5 | C17: 5 | D17: 5 | E17: 5 | F17: 5 | G17: 6 | H17: 6 | I17: 6
A18: Quebec | B18: 399 | C18: 409 | D18: 425 | E18: 435 | F18: 453 | G18: 471 | H18: 489 | I18: 506
A19: Saskatchewan | B19: 44 | C19: 46 | D19: 46 | E19: 52 | F19: 54 | G19: 56 | H19: 58 | I19: 60
A20: Yukon | B20: 1 | C20: 1 | D20: 1 | E20: 1 | F20: 1 | G20: 1 | H20: 1 | I20: 1
A21: TOTAL CANADA | B21: 1486 | C21: 1551 | D21: 1616 | E21: 1691 | F21: 1761 | G21: 1831 | H21: 1901 | I21: 1966
A23: COMPARABLE STORE SALES GROWTH %
A24: Comparable Store Sales Growth % | B24: 0.12 | C24: 0.128 | D24: 0.046 | E24: 0.042 | F24: 0.0425 | G24: 0.04 | H24: 0.0375 | I24: 0.035
A25: Transaction Growth % | B25: 0.146 | C25: 0.123 | D25: 0.064 | E25: 0.024 | F25: 0.025 | G25: 0.023 | H25: 0.021 | I25: 0.02
A26: Average Transaction Size Growth % | B26: -0.022 | C26: 0.004 | D26: -0.017 | E26: 0.017 | F26: 0.017 | G26: 0.017 | H26: 0.016 | I26: 0.015
A28: STORE PRODUCTIVITY
A29: Sales per Store | B29: ='Historical & Assumptions'!B4/'Operating Drivers'!B4 -> 3.4002295 | C29: ='Historical & Assumptions'!C4/'Operating Drivers'!C4 -> 3.7829452 | D29: ='Historical & Assumptions'!D4/'Operating Drivers'!D4 -> 3.9685303 | E29: 4.022 | F29: =F33/F4 -> 4.1226517 | G29: =G33/G4 -> 4.2227684 | H29: =H33/H4 -> 4.3174119 | I29: =I33/I4 -> 4.4126256
A30: Sales per Store Growth % | B30: 0.1157 | C30: =(C29/B29)-1 -> 0.11255585 | D30: =(D29/C29)-1 -> 0.04905837 | E30: =(E29/D29)-1 -> 0.013473421 | F30: =(F29/E29)-1 -> 0.025025276 | G30: =(G29/F29)-1 -> 0.024284544 | H30: =(H29/G29)-1 -> 0.022412678 | I30: =(I29/H29)-1 -> 0.022053408
A32: CANADA REVENUE DRIVERS
A33: Canada Revenue | B33: ='Historical & Assumptions'!B4 -> 5052.741 | C33: ='Historical & Assumptions'!C4 -> 5867.348 | D33: ='Historical & Assumptions'!D4 -> 6413.145 | E33: =6800.927 -> 6800.927 | F33: =E33*(1+F34) -> 7259.9896 | G33: =F33*(1+G34) -> 7731.8889 | H33: =G33*(1+H34) -> 8207.4001 | I33: =H33*(1+I34) -> 8675.2219
A34: Canada Revenue Growth % | B34: ='Historical & Assumptions'!B5 -> 0.167 | C34: ='Historical & Assumptions'!C5 -> 0.16122081 | D34: ='Historical & Assumptions'!D5 -> 0.093022776 | E34: 0.0605 | F34: =F24+F37 -> 0.0675 | G34: =G24+G37 -> 0.065 | H34: =H24+H37 -> 0.0615 | I34: =I24+I37 -> 0.057
A35: Comparable Store Sales Growth % | B35: =B24 -> 0.12 | C35: =C24 -> 0.128 | D35: =D24 -> 0.046 | E35: =E24 -> 0.042 | F35: =F24 -> 0.0425 | G35: =G24 -> 0.04 | H35: =H24 -> 0.0375 | I35: =I24 -> 0.035
A36: Net New Stores | B36: =B5 -> 65 | C36: =C5 -> 65 | D36: =D5 -> 65 | E36: =E5 -> 75 | F36: =F5 -> 70 | G36: =G5 -> 70 | H36: =H5 -> 70 | I36: =I5 -> 65
A37: Non-comparable Other Growth % | B37: =B34-B35 -> 0.047 | C37: =C34-C35 -> 0.033220811 | D37: =D34-D35 -> 0.047022776 | E37: =E34-E35 -> 0.0185 | F37: 0.025 | G37: 0.025 | H37: 0.024 | I37: 0.022
A39: AUSTRALIA / DOLLARAMA AUSTRALIA
A40: Ending Store Count | B40: 0 | C40: 0 | D40: 0 | E40: 402 | F40: =E40+F41 -> 422 | G40: =F40+G41 -> 452 | H40: =G40+H41 -> 487 | I40: =H40+I41 -> 527
A41: Net New Stores | B41: 0 | C41: 0 | D41: 0 | E41: 7 | F41: 20 | G41: 30 | H41: 35 | I41: 40
A42: Store Growth % | B42: 0 | C42: 0 | D42: 0 | E42: 0 | F42: =(F40/E40)-1 -> 0.049751244 | G42: =(G40/F40)-1 -> 0.071090047 | H42: =(H40/G40)-1 -> 0.077433628 | I42: =(I40/H40)-1 -> 0.082135524
A43: Australia Revenue | B43: 0 | C43: 0 | D43: 0 | E43: 454.827 | F43: 770 | G43: 831.6 | H43: 906.444 | I43: 997.088
A45: CONSOLIDATED OUTPUT
A46: Consolidated Revenue | B46: ='Historical & Assumptions'!B4 -> 5052.741 | C46: ='Historical & Assumptions'!C4 -> 5867.348 | D46: ='Historical & Assumptions'!D4 -> 6413.145 | E46: ='Historical & Assumptions'!E4 -> 7255.754 | F46: =F33+F43 -> 8029.9896 | G46: =G33+G43 -> 8563.4889 | H46: =H33+H43 -> 9113.8441 | I46: =I33+I43 -> 9672.3099
A47: Consolidated Revenue Growth % | B47: ='Historical & Assumptions'!B5 -> 0.167 | C47: ='Historical & Assumptions'!C5 -> 0.16122081 | D47: ='Historical & Assumptions'!D5 -> 0.093022776 | E47: ='Historical & Assumptions'!E5 -> 0.1313878 | F47: =(F46/E46)-1 -> 0.10670643 | G47: =(G46/F46)-1 -> 0.066438358 | H47: =(H46/G46)-1 -> 0.064267634 | I47: =(I46/H46)-1 -> 0.061276647

Sheet Revenue
A1: DOLLARAMA INC. | Revenue CAD in millions | FY2023A–FY2030E
A3: Fiscal Year | B3: FY2023A | C3: FY2024A | D3: FY2025A | E3: FY2026A | F3: FY2027E | G3: FY2028E | H3: FY2029E | I3: FY2030E
A4: CANADA REVENUE BUILD
A5: Ending Store Count | B5: ='Operating Drivers'!B4 -> 1486 | C5: ='Operating Drivers'!C4 -> 1551 | D5: ='Operating Drivers'!D4 -> 1616 | E5: ='Operating Drivers'!E4 -> 1691 | F5: ='Operating Drivers'!F4 -> 1761 | G5: ='Operating Drivers'!G4 -> 1831 | H5: ='Operating Drivers'!H4 -> 1901 | I5: ='Operating Drivers'!I4 -> 1966
A6: Net New Stores | B6: ='Operating Drivers'!B5 -> 65 | C6: ='Operating Drivers'!C5 -> 65 | D6: ='Operating Drivers'!D5 -> 65 | E6: ='Operating Drivers'!E5 -> 75 | F6: ='Operating Drivers'!F5 -> 70 | G6: ='Operating Drivers'!G5 -> 70 | H6: ='Operating Drivers'!H5 -> 70 | I6: ='Operating Drivers'!I5 -> 65
A7: Comparable Store Sales Growth % | B7: ='Operating Drivers'!B24 -> 0.12 | C7: ='Operating Drivers'!C24 -> 0.128 | D7: ='Operating Drivers'!D24 -> 0.046 | E7: ='Operating Drivers'!E24 -> 0.042 | F7: ='Operating Drivers'!F24 -> 0.0425 | G7: ='Operating Drivers'!G24 -> 0.04 | H7: ='Operating Drivers'!H24 -> 0.0375 | I7: ='Operating Drivers'!I24 -> 0.035
A8: Non-comparable Other Growth % | B8: ='Operating Drivers'!B37 -> 0.047 | C8: ='Operating Drivers'!C37 -> 0.033220811 | D8: ='Operating Drivers'!D37 -> 0.047022776 | E8: ='Operating Drivers'!E37 -> 0.0185 | F8: ='Operating Drivers'!F37 -> 0.025 | G8: ='Operating Drivers'!G37 -> 0.025 | H8: ='Operating Drivers'!H37 -> 0.024 | I8: ='Operating Drivers'!I37 -> 0.022
A9: Canada Revenue Growth % | B9: ='Operating Drivers'!B34 -> 0.167 | C9: ='Operating Drivers'!C34 -> 0.16122081 | D9: ='Operating Drivers'!D34 -> 0.093022776 | E9: ='Operating Drivers'!E34 -> 0.0605 | F9: ='Operating Drivers'!F34 -> 0.0675 | G9: ='Operating Drivers'!G34 -> 0.065 | H9: ='Operating Drivers'!H34 -> 0.0615 | I9: ='Operating Drivers'!I34 -> 0.057
A10: Canada Revenue | B10: ='Operating Drivers'!B33 -> 5052.741 | C10: ='Operating Drivers'!C33 -> 5867.348 | D10: ='Operating Drivers'!D33 -> 6413.145 | E10: ='Operating Drivers'!E33 -> 6800.927 | F10: ='Operating Drivers'!F33 -> 7259.9896 | G10: ='Operating Drivers'!G33 -> 7731.8889 | H10: ='Operating Drivers'!H33 -> 8207.4001 | I10: ='Operating Drivers'!I33 -> 8675.2219
A12: AUSTRALIA REVENUE BUILD
A13: Ending Store Count | E13: ='Operating Drivers'!E40 -> 402 | F13: ='Operating Drivers'!F40 -> 422 | G13: ='Operating Drivers'!G40 -> 452 | H13: ='Operating Drivers'!H40 -> 487 | I13: ='Operating Drivers'!I40 -> 527
A14: Net New Stores | E14: ='Operating Drivers'!E41 -> 7 | F14: ='Operating Drivers'!F41 -> 20 | G14: ='Operating Drivers'!G41 -> 30 | H14: ='Operating Drivers'!H41 -> 35 | I14: ='Operating Drivers'!I41 -> 40
A15: Australia Revenue | E15: ='Operating Drivers'!E43 -> 454.827 | F15: ='Operating Drivers'!F43 -> 770 | G15: ='Operating Drivers'!G43 -> 831.6 | H15: ='Operating Drivers'!H43 -> 906.444 | I15: ='Operating Drivers'!I43 -> 997.088
A17: CONSOLIDATED REVENUE
A18: Canada Revenue | B18: {=B10:I10} -> 5052.741 | C18: 5867.348 | D18: 6413.145 | E18: 6800.927 | F18: 7259.9896 | G18: 7731.8889 | H18: 8207.4001 | I18: 8675.2219
A19: Australia Revenue | B19: {=B15:I15} -> 0 | C19: 0 | D19: 0 | E19: 454.827 | F19: 770 | G19: 831.6 | H19: 906.444 | I19: 997.088
A20: Consolidated Revenue | B20: =B18+B19 -> 5052.741 | C20: =C18+C19 -> 5867.348 | D20: =D18+D19 -> 6413.145 | E20: =E18+E19 -> 7255.754 | F20: =F18+F19 -> 8029.9896 | G20: =G18+G19 -> 8563.4889 | H20: =H18+H19 -> 9113.8441 | I20: =I18+I19 -> 9672.3099
A21: Consolidated Revenue Growth % | B21: ='Operating Drivers'!B47 -> 0.167 | C21: ='Operating Drivers'!C47 -> 0.16122081 | D21: ='Operating Drivers'!D47 -> 0.093022776 | E21: ='Operating Drivers'!E47 -> 0.1313878 | F21: ='Operating Drivers'!F47 -> 0.10670643 | G21: ='Operating Drivers'!G47 -> 0.066438358 | H21: ='Operating Drivers'!H47 -> 0.064267634 | I21: ='Operating Drivers'!I47 -> 0.061276647

Sheet Operating Model
A1: DOLLARAMA INC. | Operating Model CAD in millions | FY2023A–FY2030E
A3: Fiscal Year | B3: FY2023A | C3: FY2024A | D3: FY2025A | E3: FY2026A | F3: FY2027E | G3: FY2028E | H3: FY2029E | I3: FY2030E
A4: Revenue | B4: ='Historical & Assumptions'!B4 -> 5052.741 | C4: ='Historical & Assumptions'!C4 -> 5867.348 | D4: ='Historical & Assumptions'!D4 -> 6413.145 | E4: ='Historical & Assumptions'!E4 -> 7255.754 | F4: =Revenue!F20 -> 8029.9896 | G4: =Revenue!G20 -> 8563.4889 | H4: =Revenue!H20 -> 9113.8441 | I4: =Revenue!I20 -> 9672.3099
A5: Revenue Growth % | B5: =Revenue!B21 -> 0.167 | C5: =Revenue!C21 -> 0.16122081 | D5: =Revenue!D21 -> 0.093022776 | E5: =Revenue!E21 -> 0.1313878 | F5: =Revenue!F21 -> 0.10670643 | G5: =Revenue!G21 -> 0.066438358 | H5: =Revenue!H21 -> 0.064267634 | I5: =Revenue!I21 -> 0.061276647
A6: COGS | B6: 2854.535 | C6: 3253.907 | D6: 3519.399 | E6: 3987.089 | F6: =F4-F7 -> 4488.7642 | G6: =G4-G7 -> 4769.8633 | H6: =H4-H7 -> 5058.1835 | I6: =I4-I7 -> 5348.7874
A7: Gross Profit | B7: 2198.206 | C7: 2613.441 | D7: 2893.746 | E7: 3268.665 | F7: =F4*F8 -> 3541.2254 | G7: =G4*G8 -> 3793.6256 | H7: =H4*H8 -> 4055.6606 | I7: =I4*I8 -> 4323.5225
A8: Gross Margin % | B8: ='Historical & Assumptions'!B8 -> 0.43505218 | C8: ='Historical & Assumptions'!C8 -> 0.44542117 | D8: ='Historical & Assumptions'!D8 -> 0.45122105 | E8: ='Historical & Assumptions'!E8 -> 0.45049281 | F8: 0.441 | G8: 0.443 | H8: 0.445 | I8: 0.447
A9: SG%A | B9: ='Historical & Assumptions'!B9 -> 720.312 | C9: ='Historical & Assumptions'!C9 -> 844.871 | D9: ='Historical & Assumptions'!D9 -> 930.168 | E9: ='Historical & Assumptions'!E9 -> 1093.289 | F9: =F4*F10 -> 1204.4984 | G9: =G4*G10 -> 1275.9598 | H9: =H4*H10 -> 1348.8489 | I9: =I4*I10 -> 1421.8296
A10: SG&A % of Revenue | B10: ='Historical & Assumptions'!B10 -> 0.14255866 | C10: ='Historical & Assumptions'!C10 -> 0.14399538 | D10: ='Historical & Assumptions'!D10 -> 0.14504085 | E10: ='Historical & Assumptions'!E10 -> 0.1506789 | F10: 0.15 | G10: 0.149 | H10: 0.148 | I10: 0.147
A11: EBITDA | B11: =B7-B9 -> 1477.894 | C11: =C7-C9 -> 1768.57 | D11: =D7-D9 -> 1963.578 | E11: =E7-E9 -> 2175.376 | F11: =F4*F12 -> 2336.727 | G11: =G4*G12 -> 2517.6657 | H11: =H4*H12 -> 2706.8117 | I11: =I4*I12 -> 2901.693
A12: EBITDA Margin % | B12: ='Historical & Assumptions'!B14 -> 0.29249352 | C12: ='Historical & Assumptions'!C14 -> 0.30142579 | D12: ='Historical & Assumptions'!D14 -> 0.3061802 | E12: ='Historical & Assumptions'!E14 -> 0.29981391 | F12: 0.291 | G12: 0.294 | H12: 0.297 | I12: 0.3
A13: D & A | B13: ='Historical & Assumptions'!B11 -> 331.792 | C13: ='Historical & Assumptions'!C11 -> 348.142 | D13: ='Historical & Assumptions'!D11 -> 382.805 | E13: ='Historical & Assumptions'!E11 -> 429.053 | F13: =F14*F4 -> 489.47748 | G13: =G14*G4 -> 521.99756 | H13: =H14*H4 -> 555.54511 | I13: =I14*I4 -> 589.58705
A14: D & A % of Revenue | B14: ='Historical & Assumptions'!B12 -> 0.065665745 | C14: ='Historical & Assumptions'!C12 -> 0.059335495 | D14: ='Historical & Assumptions'!D12 -> 0.059690682 | E14: ='Historical & Assumptions'!E12 -> 0.059132793 | F14: =AVERAGE(B14:E14) -> 0.060956179 | G14: 0.060956179 | H14: 0.060956179 | I14: 0.060956179
A15: Operating Income (EBIT) | B15: =B11-B13 -> 1146.102 | C15: =C11-C13 -> 1420.428 | D15: =D11-D13 -> 1580.773 | E15: =E11-E13 -> 1746.323 | F15: =F11-F13 -> 1847.2495 | G15: =G11-G13 -> 1995.6682 | H15: =H11-H13 -> 2151.2666 | I15: =I11-I13 -> 2312.1059
A16: Operating Margin % | B16: ='Historical & Assumptions'!B16 -> 0.22682778 | C16: ='Historical & Assumptions'!C16 -> 0.24209029 | D16: ='Historical & Assumptions'!D16 -> 0.24648951 | E16: ='Historical & Assumptions'!E16 -> 0.24068112 | F16: 0.232 | G16: 0.235 | H16: 0.238 | I16: 0.241
A17: Earning before tax | B17: =B15-'Working Capital & Financing'!B23 -> 1030.708 | C17: =C15-'Working Capital & Financing'!C23 -> 1275.586 | D17: =D15-'Working Capital & Financing'!D23 -> 1416.991 | E17: =E15-'Working Capital & Financing'!E23 -> 1562.303 | F17: =F15-'Working Capital & Financing'!F23 -> 1654.0285 | G17: =G15-'Working Capital & Financing'!G23 -> 1792.7861 | H17: =H15-'Working Capital & Financing'!H23 -> 1938.2404 | I17: =I15-'Working Capital & Financing'!I23 -> 2088.4284
A18: Tax Rate | B18: 0.255 | C18: 0.252 | D18: 0.245 | E18: 0.258 | F18: 0.255 | G18: 0.255 | H18: 0.255 | I18: 0.255
A19: Income tax | B19: =B17*B18 -> 262.83054 | C19: =C17*C18 -> 321.44767 | D19: =D17*D18 -> 347.1628 | E19: =E17*E18 -> 403.07417 | F19: =F17*F18 -> 421.77726 | G19: =G17*G18 -> 457.16046 | H19: =H17*H18 -> 494.25131 | I19: =I17*I18 -> 532.54925

Sheet PP&E & Capex
A1: DOLLARAMA INC. | PP&E & Capex CAD in millions | FY2023A–FY2030E
A3: Fiscal Year | B3: FY2023A | C3: FY2024A | D3: FY2025A | E3: FY2026A | F3: FY2027E | G3: FY2028E | H3: FY2029E | I3: FY2030E
A4: CAPITAL EXPENDITURES
A5: Revenue | B5: ='Historical & Assumptions'!B4 -> 5052.741 | C5: ='Historical & Assumptions'!C4 -> 5867.348 | D5: ='Historical & Assumptions'!D4 -> 6413.145 | E5: ='Historical & Assumptions'!E4 -> 7255.754 | F5: ='Historical & Assumptions'!F4 -> 8029.9896 | G5: ='Historical & Assumptions'!G4 -> 8563.4889 | H5: ='Historical & Assumptions'!H4 -> 9113.8441 | I5: ='Historical & Assumptions'!I4 -> 9672.3099
A6: CapEx | B6: ='Historical & Assumptions'!B42 -> 156.827 | C6: ='Historical & Assumptions'!C42 -> 278.764 | D6: ='Historical & Assumptions'!D42 -> 243.45 | E6: ='Historical & Assumptions'!E42 -> 272.781 | F6: =F7*F5 -> 313.16959 | G6: =G7*G5 -> 333.97607 | H6: =H7*H5 -> 346.32607 | I6: =I7*I5 -> 367.54777
A7: CapEx % of Revenue | B7: =B6/B5 -> 0.031038005 | C7: =C6/C5 -> 0.047511073 | D7: =D6/D5 -> 0.037961094 | E7: =E6/E5 -> 0.037595128 | F7: 0.039 | G7: 0.039 | H7: 0.038 | I7: 0.038
A9: PROPERTY, PLANT & EQUIPMENT
A10: Beginning PP&E | B10: 761.876 | C10: =B14 -> 802.75 | D10: =C14 -> 950.994 | E10: =D14 -> 1046.39 | F10: =E14 -> 1258.499 | G10: =F14 -> 1414.5017 | H10: =G14 -> 1573.63 | I10: =H14 -> 1727.9605
A11: PP&E additions | B11: ='Historical & Assumptions'!B40 -> 134.049 | C11: ='Historical & Assumptions'!C40 -> 252.673 | D11: ='Historical & Assumptions'!D40 -> 212.828 | E11: ='Historical & Assumptions'!E40 -> 248.747 | F11: =0.9*F6 -> 281.85263 | G11: =0.9*G6 -> 300.57846 | H11: =0.9*H6 -> 311.69347 | I11: =0.9*I6 -> 330.793
A12: Depreciation | B12: ='Historical & Assumptions'!B31 -> 92.956 | C12: ='Historical & Assumptions'!C31 -> 103.923 | D12: ='Historical & Assumptions'!D31 -> 116.238 | E12: ='Historical & Assumptions'!E31 -> 104.806 | F12: =F10*0.1 -> 125.8499 | G12: =G10*0.1 -> 141.45017 | H12: =H10*0.1 -> 157.363 | I12: =I10*0.1 -> 172.79605
A13: Other Adjustments | B13: =B14-B10-B11+B12 -> -0.219 | C13: =C14-C10-C11+C12 -> -0.506 | D13: =D14-D10-D11+D12 -> -1.194 | E13: =E14-E10-E11+E12 -> 68.168 | F13: 0 | G13: 0 | H13: 0 | I13: 0
A14: Ending PP&E | B14: ='Historical & Assumptions'!B30 -> 802.75 | C14: ='Historical & Assumptions'!C30 -> 950.994 | D14: ='Historical & Assumptions'!D30 -> 1046.39 | E14: ='Historical & Assumptions'!E30 -> 1258.499 | F14: =F10+F11+F13-F12 -> 1414.5017 | G14: =G10+G11+G13-G12 -> 1573.63 | H14: =H10+H11+H13-H12 -> 1727.9605 | I14: =I10+I11+I13-I12 -> 1885.9574
A16: DEPRECIATION & AMORTIZATION
A17: D&A | B17: ='Historical & Assumptions'!B11 -> 331.792 | C17: ='Historical & Assumptions'!C11 -> 348.142 | D17: ='Historical & Assumptions'!D11 -> 382.805 | E17: ='Historical & Assumptions'!E11 -> 429.053 | F17: ='Historical & Assumptions'!F11 -> 489.47748 | G17: ='Historical & Assumptions'!G11 -> 521.99756 | H17: ='Historical & Assumptions'!H11 -> 555.54511 | I17: ='Historical & Assumptions'!I11 -> 589.58705
A18: D&A % of Revenue | B18: ='Historical & Assumptions'!B12 -> 0.065665745 | C18: ='Historical & Assumptions'!C12 -> 0.059335495 | D18: ='Historical & Assumptions'!D12 -> 0.059690682 | E18: ='Historical & Assumptions'!E12 -> 0.059132793 | F18: ='Historical & Assumptions'!F12 -> 0.060956179 | G18: ='Historical & Assumptions'!G12 -> 0.060956179 | H18: ='Historical & Assumptions'!H12 -> 0.060956179 | I18: ='Historical & Assumptions'!I12 -> 0.060956179
A20: MODEL CHECKS
A21: PP&E Roll-Forward Check | B21: =ROUND(B14-B10-B11+B12-B13,2) -> 0 | C21: =ROUND(C14-C10-C11+C12-C13,2) -> 0 | D21: =ROUND(D14-D10-D11+D12-D13,2) -> 0 | E21: =ROUND(E14-E10-E11+E12-E13,2) -> 0 | F21: =ROUND(F14-F10-F11+F12-F13,2) -> 0 | G21: =ROUND(G14-G10-G11+G12-G13,2) -> 0 | H21: =ROUND(H14-H10-H11+H12-H13,2) -> 0 | I21: =ROUND(I14-I10-I11+I12-I13,2) -> 0

Sheet Working Capital & Financing
A1: DOLLARAMA INC. | Capital & Financing CAD in millions | FY2023A–FY2030E
A3: Fiscal Year | B3: FY2023A | C3: FY2024A | D3: FY2025A | E3: FY2026A | F3: FY2027E | G3: FY2028E | H3: FY2029E | I3: FY2030E
A4: WORKING CAPITAL
A5: Revenue | B5: {='Historical & Assumptions'!B4:I4} -> 5052.741 | C5: 5867.348 | D5: 6413.145 | E5: 7255.754 | F5: 8029.9896 | G5: 8563.4889 | H5: 9113.8441 | I5: 9672.3099
A6: COGS | B6: {='Historical & Assumptions'!B6:I6} -> 2854.535 | C6: 3253.907 | D6: 3519.399 | E6: 3987.089 | F6: 4488.7642 | G6: 4769.8633 | H6: 5058.1835 | I6: 5348.7874
A7: Accounts Receivable | B7: {='Historical & Assumptions'!B27:B29} -> 56.29 | C7: {='Historical & Assumptions'!C27:C29} -> 32.474 | D7: {='Historical & Assumptions'!D27:D29} -> 46.638 | E7: {='Historical & Assumptions'!E27:E29} -> 38.5 | F7: =(F5*F13)/365 -> 43.999943 | G7: =(G5*G13)/365 -> 46.923227 | H7: =(H5*H13)/365 -> 49.938872 | I7: =(I5*I13)/365 -> 52.998958
A8: Inventory | B8: 957.172 | C8: 916.812 | D8: 921.095 | E8: 1103.175 | F8: =(F6*F14)/365 -> 1229.7984 | G8: =(G6*G14)/365 -> 1280.6756 | H8: =(H6*H14)/365 -> 1330.3715 | I8: =(I6*I14)/365 -> 1377.4959
A9: Accounts Payable & Accruals | B9: 336.862 | C9: 334.357 | D9: 354.9 | E9: 461.766 | F9: =(F6*F15)/365 -> 516.51533 | G9: =(G6*G15)/365 -> 548.86098 | H9: =(H6*H15)/365 -> 595.89559 | I9: =(I6*I15)/365 -> 630.13111
A10: Net Working Capital | B10: =B7+B8-B9 -> 676.6 | C10: =C7+C8-C9 -> 614.929 | D10: =D7+D8-D9 -> 612.833 | E10: =E7+E8-E9 -> 679.909 | F10: =F7+F8-F9 -> 757.28302 | G10: =G7+G8-G9 -> 778.73787 | H10: =H7+H8-H9 -> 784.41483 | I10: =I7+I8-I9 -> 800.36377
A12: WORKING CAPITAL DRIVERS
A13: DSO (Days) | B13: =(B7/B5)*365 -> 4.0662781 | C13: =(C7/C5)*365 -> 2.0201648 | D13: =(D7/D5)*365 -> 2.6543716 | E13: =(E7/E5)*365 -> 1.9367388 | F13: 2 | G13: 2 | H13: 2 | I13: 2
A14: DIO (Days) | B14: =(B8/B6)*365 -> 122.39043 | C14: =(C8/C6)*365 -> 102.84141 | D14: =(D8/D6)*365 -> 95.527582 | E14: =(E8/E6)*365 -> 100.99069 | F14: 100 | G14: 98 | H14: 96 | I14: 94
A15: DPO (Days) | B15: =(B9/B6)*365 -> 43.073436 | C15: =(C9/C6)*365 -> 37.505775 | D15: =(D9/D6)*365 -> 36.806995 | E15: =(E9/E6)*365 -> 42.272593 | F15: 42 | G15: 42 | H15: 43 | I15: 43
A16: Cash Conversion Cycle (Days) | B16: =B13+B14-B15 -> 83.383277 | C16: =C13+C14-C15 -> 67.355798 | D16: =D13+D14-D15 -> 61.374959 | E16: =E13+E14-E15 -> 60.654837 | F16: =F13+F14-F15 -> 60 | G16: =G13+G14-G15 -> 58 | H16: =H13+H14-H15 -> 55 | I16: =I13+I14-I15 -> 53
A18: FINANCING
A19: Cash | B19: ='Historical & Assumptions'!B26 -> 101.261 | C19: ='Historical & Assumptions'!C26 -> 313.915 | D19: ='Historical & Assumptions'!D26 -> 122.685 | E19: ='Historical & Assumptions'!E26 -> 331.569 | F19: 0 | G19: 0 | H19: 0 | I19: 0
A20: Total Debt | B20: ='Historical & Assumptions'!B34 -> 2251.903 | C20: ='Historical & Assumptions'!C34 -> 2264.394 | D20: ='Historical & Assumptions'!D34 -> 2282.679 | E20: ='Historical & Assumptions'!E34 -> 2625.121 | F20: =E20*1.05 -> 2756.3771 | G20: =F20*1.05 -> 2894.1959 | H20: =G20*1.05 -> 3038.9057 | I20: =H20*1.05 -> 3190.851
A21: Lease Liabilities | B21: ='Historical & Assumptions'!B35 -> 1960.743 | C21: ='Historical & Assumptions'!C35 -> 2069.229 | D21: ='Historical & Assumptions'!D35 -> 2426.977 | E21: ='Historical & Assumptions'!E35 -> 2770.473 | F21: =E21*1.08 -> 2992.1108 | G21: =F21*1.08 -> 3231.4797 | H21: =G21*1.08 -> 3489.9981 | I21: =H21*1.08 -> 3769.1979
A22: Net Debt | B22: =B20-B19 -> 2150.642 | C22: =C20-C19 -> 1950.479 | D22: =D20-D19 -> 2159.994 | E22: =E20-E19 -> 2293.552 | F22: 0 | G22: 0 | H22: 0 | I22: 0
A23: Net Financing Costs | B23: ='Historical & Assumptions'!B17 -> 115.394 | C23: ='Historical & Assumptions'!C17 -> 144.842 | D23: ='Historical & Assumptions'!D17 -> 163.782 | E23: ='Historical & Assumptions'!E17 -> 184.02 | F23: =E23*1.05 -> 193.221 | G23: =F23*1.05 -> 202.88205 | H23: =G23*1.05 -> 213.02615 | I23: =H23*1.05 -> 223.67746

Sheet P & L
A1: DOLLARAMA INC. | Income Statement CAD in millions | FY2023A–FY2030E
A3: Fiscal Year | B3: FY2023A | C3: FY2024A | D3: FY2025A | E3: FY2026A | F3: FY2027E | G3: FY2028E | H3: FY2029E | I3: FY2030E
A4: Revenue | B4: =Revenue!B20 -> 5052.741 | C4: =Revenue!C20 -> 5867.348 | D4: =Revenue!D20 -> 6413.145 | E4: =Revenue!E20 -> 7255.754 | F4: =Revenue!F20 -> 8029.9896 | G4: =Revenue!G20 -> 8563.4889 | H4: =Revenue!H20 -> 9113.8441 | I4: =Revenue!I20 -> 9672.3099
A5: COGS | B5: ='Operating Model'!B6 -> 2854.535 | C5: ='Operating Model'!C6 -> 3253.907 | D5: ='Operating Model'!D6 -> 3519.399 | E5: ='Operating Model'!E6 -> 3987.089 | F5: ='Operating Model'!F6 -> 4488.7642 | G5: ='Operating Model'!G6 -> 4769.8633 | H5: ='Operating Model'!H6 -> 5058.1835 | I5: ='Operating Model'!I6 -> 5348.7874
A6: Gross Profit | B6: ='Operating Model'!B7 -> 2198.206 | C6: ='Operating Model'!C7 -> 2613.441 | D6: ='Operating Model'!D7 -> 2893.746 | E6: ='Operating Model'!E7 -> 3268.665 | F6: ='Operating Model'!F7 -> 3541.2254 | G6: ='Operating Model'!G7 -> 3793.6256 | H6: ='Operating Model'!H7 -> 4055.6606 | I6: ='Operating Model'!I7 -> 4323.5225
A7: Gross Margin % | B7: ='Operating Model'!B8 -> 0.43505218 | C7: ='Operating Model'!C8 -> 0.44542117 | D7: ='Operating Model'!D8 -> 0.45122105 | E7: ='Operating Model'!E8 -> 0.45049281 | F7: ='Operating Model'!F8 -> 0.441 | G7: ='Operating Model'!G8 -> 0.443 | H7: ='Operating Model'!H8 -> 0.445 | I7: ='Operating Model'!I8 -> 0.447
A8: SG&A | B8: ='Operating Model'!B9 -> 720.312 | C8: ='Operating Model'!C9 -> 844.871 | D8: ='Operating Model'!D9 -> 930.168 | E8: ='Operating Model'!E9 -> 1093.289 | F8: ='Operating Model'!F9 -> 1204.4984 | G8: ='Operating Model'!G9 -> 1275.9598 | H8: ='Operating Model'!H9 -> 1348.8489 | I8: ='Operating Model'!I9 -> 1421.8296
A9: EBITDA | B9: =B6-B8 -> 1477.894 | C9: =C6-C8 -> 1768.57 | D9: =D6-D8 -> 1963.578 | E9: =E6-E8 -> 2175.376 | F9: =F6-F8 -> 2336.727 | G9: =G6-G8 -> 2517.6657 | H9: =H6-H8 -> 2706.8117 | I9: =I6-I8 -> 2901.693
A10: EBITDA Margin % | B10: =B9/B4 -> 0.29249352 | C10: =C9/C4 -> 0.30142579 | D10: =D9/D4 -> 0.3061802 | E10: =E9/E4 -> 0.29981391 | F10: =F9/F4 -> 0.291 | G10: =G9/G4 -> 0.294 | H10: =H9/H4 -> 0.297 | I10: =I9/I4 -> 0.3
A11: D & A | B11: ='Operating Model'!B13 -> 331.792 | C11: ='Operating Model'!C13 -> 348.142 | D11: ='Operating Model'!D13 -> 382.805 | E11: ='Operating Model'!E13 -> 429.053 | F11: ='Operating Model'!F13 -> 489.47748 | G11: ='Operating Model'!G13 -> 521.99756 | H11: ='Operating Model'!H13 -> 555.54511 | I11: ='Operating Model'!I13 -> 589.58705
A12: Operating Income (EBIT) | B12: =B9-B11 -> 1146.102 | C12: =C9-C11 -> 1420.428 | D12: =D9-D11 -> 1580.773 | E12: =E9-E11 -> 1746.323 | F12: =F9-F11 -> 1847.2495 | G12: =G9-G11 -> 1995.6682 | H12: =H9-H11 -> 2151.2666 | I12: =I9-I11 -> 2312.1059
A13: Net Financing Costs | B13: ='Working Capital & Financing'!B23 -> 115.394 | C13: ='Working Capital & Financing'!C23 -> 144.842 | D13: ='Working Capital & Financing'!D23 -> 163.782 | E13: ='Working Capital & Financing'!E23 -> 184.02 | F13: ='Working Capital & Financing'!F23 -> 193.221 | G13: ='Working Capital & Financing'!G23 -> 202.88205 | H13: ='Working Capital & Financing'!H23 -> 213.02615 | I13: ='Working Capital & Financing'!I23 -> 223.67746
A14: Earnings Before Tax | B14: =B12-B13 -> 1030.708 | C14: =C12-C13 -> 1275.586 | D14: =D12-D13 -> 1416.991 | E14: =E12-E13 -> 1562.303 | F14: =F12-F13 -> 1654.0285 | G14: =G12-G13 -> 1792.7861 | H14: =H12-H13 -> 1938.2404 | I14: =I12-I13 -> 2088.4284
A15: Income Taxes | B15: ='Historical & Assumptions'!B25 -> 274.244 | C15: ='Historical & Assumptions'!C25 -> 340.419 | D15: ='Historical & Assumptions'!D25 -> 378.351 | E15: ='Historical & Assumptions'!E25 -> 454.749 | F15: =F14*25.5% -> 421.77726 | G15: =G14*25.5% -> 457.16046 | H15: =H14*25.5% -> 494.25131 | I15: =I14*25.5% -> 532.54925
A16: Net Income | B16: =B14-B15 -> 756.464 | C16: =C14-C15 -> 935.167 | D16: =D14-D15 -> 1038.64 | E16: =E14-E15 -> 1107.554 | F16: =F14-F15 -> 1232.2512 | G16: =G14-G15 -> 1335.6257 | H16: =H14-H15 -> 1443.9891 | I16: =I14-I15 -> 1555.8792
A17: Net Profit Margin | B17: =B16/B4 -> 0.14971359 | C17: =C16/C4 -> 0.15938496 | D17: =D16/D4 -> 0.16195486 | E17: =E16/E4 -> 0.15264492 | F17: =F16/F4 -> 0.15345614 | G17: =G16/G4 -> 0.15596747 | H17: =H16/H4 -> 0.15843909 | I17: =I16/I4 -> 0.16085911

Sheet Balance Sheet
A1: DOLLARAMA INC. | Balance Sheet CAD in millions | FY2023A–FY2030E
A3: Fiscal Year | B3: FY2023A | C3: FY2024A | D3: FY2025A | E3: FY2026A | F3: FY2027E | G3: FY2028E | H3: FY2029E | I3: FY2030E
A4: Cash & Cash Equivalents | B4: ='Historical & Assumptions'!B26 -> 101.261 | C4: ='Historical & Assumptions'!C26 -> 313.915 | D4: ='Historical & Assumptions'!D26 -> 122.685 | E4: ='Historical & Assumptions'!E26 -> 331.569 | F4: ='Cash Flow Statement'!F22 -> 1387.6947 | G4: ='Cash Flow Statement'!G22 -> 2603.8528 | H4: ='Cash Flow Statement'!H22 -> 3953.0833 | I4: ='Cash Flow Statement'!I22 -> 5404.6832
A5: Accounts Receivable | B5: ='Working Capital & Financing'!B7 -> 56.29 | C5: ='Working Capital & Financing'!C7 -> 32.474 | D5: ='Working Capital & Financing'!D7 -> 46.638 | E5: ='Working Capital & Financing'!E7 -> 38.5 | F5: ='Working Capital & Financing'!F7 -> 43.999943 | G5: ='Working Capital & Financing'!G7 -> 46.923227 | H5: ='Working Capital & Financing'!H7 -> 49.938872 | I5: ='Working Capital & Financing'!I7 -> 52.998958
A6: Inventory | B6: ='Working Capital & Financing'!B8 -> 957.172 | C6: ='Working Capital & Financing'!C8 -> 916.812 | D6: ='Working Capital & Financing'!D8 -> 921.095 | E6: ='Working Capital & Financing'!E8 -> 1103.175 | F6: ='Working Capital & Financing'!F8 -> 1229.7984 | G6: ='Working Capital & Financing'!G8 -> 1280.6756 | H6: ='Working Capital & Financing'!H8 -> 1330.3715 | I6: ='Working Capital & Financing'!I8 -> 1377.4959
A7: Other Assets | B7: 1037.774 | C7: 1093.027 | D7: 2055.65 | E7: 2251.119 | F7: =E7*1.05 -> 2363.675 | G7: =F7*1.05 -> 2481.8587 | H7: =G7*1.05 -> 2605.9516 | I7: =H7*1.05 -> 2736.2492
A8: PP&E | B8: ='PP&E & Capex'!B14 -> 802.75 | C8: ='PP&E & Capex'!C14 -> 950.994 | D8: ='PP&E & Capex'!D14 -> 1046.39 | E8: ='PP&E & Capex'!E14 -> 1258.499 | F8: ='PP&E & Capex'!F14 -> 1414.5017 | G8: ='PP&E & Capex'!G14 -> 1573.63 | H8: ='PP&E & Capex'!H14 -> 1727.9605 | I8: ='PP&E & Capex'!I14 -> 1885.9574
A9: Intangible Assets | B9: ='Historical & Assumptions'!B32 -> 164.654 | C9: ='Historical & Assumptions'!C32 -> 167.835 | D9: ='Historical & Assumptions'!D32 -> 180.689 | E9: ='Historical & Assumptions'!E32 -> 178.281 | F9: =E9*1.02 -> 181.84662 | G9: =F9*1.02 -> 185.48355 | H9: =G9*1.02 -> 189.19322 | I9: =H9*1.02 -> 192.97709
A10: Right-of-Use Assets | B10: ='Historical & Assumptions'!B33 -> 1699.755 | C10: ='Historical & Assumptions'!C33 -> 1788.55 | D10: ='Historical & Assumptions'!D33 -> 2109.445 | E10: ='Historical & Assumptions'!E33 -> 2397.209 | F10: =E10*1.08 -> 2588.9857 | G10: =F10*1.08 -> 2796.1046 | H10: =G10*1.08 -> 3019.7929 | I10: =H10*1.08 -> 3261.3764
A11: Total Assets | B11: =SUM(B4:B10) -> 4819.656 | C11: =SUM(C4:C10) -> 5263.607 | D11: =SUM(D4:D10) -> 6482.592 | E11: =SUM(E4:E10) -> 7558.352 | F11: =SUM(F4:F10) -> 9210.502 | G11: =SUM(G4:G10) -> 10968.528 | H11: =SUM(H4:H10) -> 12876.292 | I11: =SUM(I4:I10) -> 14911.738
A13: Accounts Payable & Accruals | B13: ='Working Capital & Financing'!B9 -> 336.862 | C13: ='Working Capital & Financing'!C9 -> 334.357 | D13: ='Working Capital & Financing'!D9 -> 354.9 | E13: ='Working Capital & Financing'!E9 -> 461.766 | F13: ='Working Capital & Financing'!F9 -> 516.51533 | G13: ='Working Capital & Financing'!G9 -> 548.86098 | H13: ='Working Capital & Financing'!H9 -> 595.89559 | I13: ='Working Capital & Financing'!I9 -> 630.13111
A14: Total Debt | B14: ='Working Capital & Financing'!B20 -> 2251.903 | C14: ='Working Capital & Financing'!C20 -> 2264.394 | D14: ='Working Capital & Financing'!D20 -> 2282.679 | E14: ='Working Capital & Financing'!E20 -> 2625.121 | F14: ='Working Capital & Financing'!F20 -> 2756.3771 | G14: ='Working Capital & Financing'!G20 -> 2894.1959 | H14: ='Working Capital & Financing'!H20 -> 3038.9057 | I14: ='Working Capital & Financing'!I20 -> 3190.851
A15: Lease Liabilities | B15: {='Working Capital & Financing'!B21:I21} -> 1960.743 | C15: 2069.229 | D15: 2426.977 | E15: 2770.473 | F15: 2992.1108 | G15: 3231.4797 | H15: 3489.9981 | I15: 3769.1979
A16: Other Liabilities | B16: 241.738 | C16: 214.779 | D16: 229.778 | E16: 245.104 | F16: =E16*1.05 -> 257.3592 | G16: =F16*1.05 -> 270.22716 | H16: =G16*1.05 -> 283.73852 | I16: =H16*1.05 -> 297.92544
A17: Total Liabilities | B17: =SUM(B13:B16) -> 4791.246 | C17: =SUM(C13:C16) -> 4882.759 | D17: =SUM(D13:D16) -> 5294.334 | E17: =SUM(E13:E16) -> 6102.464 | F17: =SUM(F13:F16) -> 6522.3624 | G17: =SUM(G13:G16) -> 6944.7638 | H17: =SUM(H13:H16) -> 7408.5379 | I17: =SUM(I13:I16) -> 7888.1055
A19: Shareholders' Equity | B19: ='Historical & Assumptions'!B38 -> 28.41 | C19: ='Historical & Assumptions'!C38 -> 380.848 | D19: ='Historical & Assumptions'!D38 -> 1188.258 | E19: ='Historical & Assumptions'!E38 -> 1455.888 | F19: =E19+'P & L'!F16-'Historical & Assumptions'!G53-'Historical & Assumptions'!G52 -> 2688.1392 | G19: =F19+'P & L'!G16-'Historical & Assumptions'!H53-'Historical & Assumptions'!H52 -> 4023.7649 | H19: =G19+'P & L'!H16-'Historical & Assumptions'!I53-'Historical & Assumptions'!I52 -> 5467.754 | I19: =H19+'P & L'!I16-'Historical & Assumptions'!J53-'Historical & Assumptions'!J52 -> 7023.6332
A20: Total Liabilities & Equity | B20: =B17+B19 -> 4819.656 | C20: =C17+C19 -> 5263.607 | D20: =D17+D19 -> 6482.592 | E20: =E17+E19 -> 7558.352 | F20: =F17+F19 -> 9210.5016 | G20: =G17+G19 -> 10968.529 | H20: =H17+H19 -> 12876.292 | I20: =I17+I19 -> 14911.739
A21: Balance Sheet Check | B21: =ROUND(B11-B20,2) -> 0 | C21: =ROUND(C11-C20,2) -> 0 | D21: =ROUND(D11-D20,2) -> 0 | E21: =ROUND(E11-E20,2) -> 0 | F21: =ROUND(F11-F20,2) -> 0 | G21: =ROUND(G11-G20,2) -> 0 | H21: =ROUND(H11-H20,2) -> 0 | I21: =ROUND(I11-I20,2) -> 0

Sheet Cash Flow Statement
A1: DOLLARAMA INC. | Cash Flow Statement CAD in millions | FY2023A–FY2030E
A3: Fiscal Year | B3: FY2023A | C3: FY2024A | D3: FY2025A | E3: FY2026A | F3: FY2027E | G3: FY2028E | H3: FY2029E | I3: FY2030E
A4: Net Income | B4: {='P & L'!B16:I16} -> 756.464 | C4: 935.167 | D4: 1038.64 | E4: 1107.554 | F4: 1232.2512 | G4: 1335.6257 | H4: 1443.9891 | I4: 1555.8792
A5: D & A | B5: {='P & L'!B11:I11} -> 331.792 | C5: 348.142 | D5: 382.805 | E5: 429.053 | F5: 489.47748 | G5: 521.99756 | H5: 555.54511 | I5: 589.58705
A6: Change in Working Capital | B6: ='Historical & Assumptions'!B43 -> -351.218 | C6: ='Historical & Assumptions'!C43 -> 52.544 | D6: ='Historical & Assumptions'!D43 -> -6.752 | E6: ='Historical & Assumptions'!E43 -> -55.874 | F6: ='Working Capital & Financing'!E10-'Working Capital & Financing'!F10 -> -77.374017 | G6: ='Working Capital & Financing'!F10-'Working Capital & Financing'!G10 -> -21.454856 | H6: ='Working Capital & Financing'!G10-'Working Capital & Financing'!H10 -> -5.6769529 | I6: ='Working Capital & Financing'!H10-'Working Capital & Financing'!I10 -> -15.948942
A7: Other Operating Adjustments | B7: =B8-B4-B5-B6 -> 132.005 | C7: =C8-C4-C5-C6 -> 195.101 | D7: =D8-D4-D5-D6 -> 229.446 | E7: =E8-E4-E5-E6 -> 280.423 | F7: =E7*1.05 -> 294.44415 | G7: =F7*1.05 -> 309.16636 | H7: =G7*1.05 -> 324.62468 | I7: =H7*1.05 -> 340.85591
A8: Cash Flow from Operations | B8: ='Historical & Assumptions'!B39 -> 869.043 | C8: ='Historical & Assumptions'!C39 -> 1530.954 | D8: ='Historical & Assumptions'!D39 -> 1644.139 | E8: ='Historical & Assumptions'!E39 -> 1761.156 | F8: =SUM(F4:F7) -> 1938.7988 | G8: =SUM(G4:G7) -> 2145.3347 | H8: =SUM(H4:H7) -> 2318.4819 | I8: =SUM(I4:I7) -> 2470.3732
A10: Capex | B10: =-'PP&E & Capex'!B6 -> -156.827 | C10: =-'PP&E & Capex'!C6 -> -278.764 | D10: =-'PP&E & Capex'!D6 -> -243.45 | E10: =-'PP&E & Capex'!E6 -> -272.781 | F10: =-'PP&E & Capex'!F6 -> -313.16959 | G10: =-'PP&E & Capex'!G6 -> -333.97607 | H10: =-'PP&E & Capex'!H6 -> -346.32607 | I10: =-'PP&E & Capex'!I6 -> -367.54777
A11: Intengible asset purchase | B11: =-'Working Capital & Financing'!B23 -> -115.394 | C11: =-'Working Capital & Financing'!C23 -> -144.842 | D11: =-'Working Capital & Financing'!D23 -> -163.782 | E11: =-'Working Capital & Financing'!E23 -> -184.02 | F11: -279.2 | G11: -277.735 | H11: -275.928 | I11: -272.127
A12: Cash Flow from Investing | B12: =B10 -> -156.827 | C12: =C10 -> -278.764 | D12: =D10 -> -243.45 | E12: =E10 -> -272.781 | F12: =SUM(F10:F11) -> -592.36959 | G12: =SUM(G10:G11) -> -611.71107 | H12: =SUM(H10:H11) -> -622.25407 | I12: =SUM(I10:I11) -> -639.67477
A14: Change in Debt | B14: 365.603 | C14: ='Working Capital & Financing'!C20-'Working Capital & Financing'!B20 -> 12.491 | D14: ='Working Capital & Financing'!D20-'Working Capital & Financing'!C20 -> 18.285 | E14: ='Working Capital & Financing'!E20-'Working Capital & Financing'!D20 -> 342.442 | F14: ='Working Capital & Financing'!F20-'Working Capital & Financing'!E20 -> 131.25605 | G14: ='Working Capital & Financing'!G20-'Working Capital & Financing'!F20 -> 137.81885 | H14: ='Working Capital & Financing'!H20-'Working Capital & Financing'!G20 -> 144.7098 | I14: ='Working Capital & Financing'!I20-'Working Capital & Financing'!H20 -> 151.94528
A15: Lease Principal Payments | B15: =-'Historical & Assumptions'!B44 -> -253.566 | C15: =-'Historical & Assumptions'!C44 -> -284.836 | D15: =-'Historical & Assumptions'!D44 -> -317.829 | E15: =-'Historical & Assumptions'!E44 -> -390.333 | F15: =E15*1.08 -> -421.55964 | G15: =F15*1.08 -> -455.28441 | H15: =G15*1.08 -> -491.70716 | I15: =H15*1.08 -> -531.04374
A16: Share Repurchases | B16: {=-'Historical & Assumptions'!C52:J52} -> 0 | C16: 0 | D16: 0 | E16: 0 | F16: 0 | G16: 0 | H16: 0 | I16: 0
A17: Dividends Paid | B17: {=-'Historical & Assumptions'!C53:J53} -> 0 | C17: 0 | D17: 0 | E17: 0 | F17: 0 | G17: 0 | H17: 0 | I17: 0
A18: Cash Flow from Financing | B18: =SUM(B14:B17) -> 112.037 | C18: =SUM(C14:C17) -> -272.345 | D18: =SUM(D14:D17) -> -299.544 | E18: =SUM(E14:E17) -> -47.891 | F18: =SUM(F14:F17) -> -290.30359 | G18: =SUM(G14:G17) -> -317.46556 | H18: =SUM(H14:H17) -> -346.99737 | I18: =SUM(I14:I17) -> -379.09845
A20: Net Change in Cash | B20: =B8+B12+B18 -> 824.253 | C20: =C8+C12+C18 -> 979.845 | D20: =D8+D12+D18 -> 1101.145 | E20: =E8+E12+E18 -> 1440.484 | F20: =F8+F12+F18 -> 1056.1257 | G20: =G8+G12+G18 -> 1216.1581 | H20: =H8+H12+H18 -> 1349.2305 | I20: =I8+I12+I18 -> 1451.6
A21: Beginning Cash | B21: 71.058 | C21: =B22 -> 101.261 | D21: =C22 -> 313.915 | E21: =D22 -> 122.685 | F21: =E22 -> 331.569 | G21: =F22 -> 1387.6947 | H21: =G22 -> 2603.8528 | I21: =H22 -> 3953.0833
A22: Ending Cash | B22: ='Balance Sheet'!B4 -> 101.261 | C22: ='Balance Sheet'!C4 -> 313.915 | D22: ='Balance Sheet'!D4 -> 122.685 | E22: ='Balance Sheet'!E4 -> 331.569 | F22: =E22+F20 -> 1387.6947 | G22: =F22+G20 -> 2603.8528 | H22: =G22+H20 -> 3953.0833 | I22: =H22+I20 -> 5404.6832

Sheet Budget & Reforecast
A1: DOLLARAMA INC. | Budget & Reforecast CAD in millions
A3: Metrics | B3: FY2027 Budget | C3: FY2027 Reforecast | D3: FY2028 Reforecast | E3: FY2029 Reforecast | F3: FY2030 Reforecast
A4: Revenue | B4: ='Operating Model'!F4 -> 8029.9896 | C4: ='Operating Model'!E4*(1+'Budget & Reforecast'!C5) -> 7957.432 | D4: =C4*(1+D5) -> 8474.6651 | E4: =D4*(1+E5) -> 9008.569 | F4: =E4*(1+F5) -> 9549.0832
A5: Revenue Growth % | B5: ='Operating Model'!F5 -> 0.10670643 | C5: =B5-1% -> 0.096706425 | D5: 0.065 | E5: 0.063 | F5: 0.06
A6: COGS | B6: ='Operating Model'!F6 -> 4488.7642 | C6: =C4*C7 -> 4487.9917 | D6: =D4*D7 -> 4762.7618 | E6: =E4*E7 -> 5044.7986 | F6: =F4*F7 -> 5328.3884
A7: COGS % | B7: =B6/B4 -> 0.559 | C7: =B7+0.5% -> 0.564 | D7: 0.562 | E7: 0.56 | F7: 0.558
A8: Gross Margin % | B8: ='Operating Model'!F8 -> 0.441 | C8: =1-C7 -> 0.436 | D8: =1-D7 -> 0.438 | E8: =1-E7 -> 0.44 | F8: =1-F7 -> 0.442
A9: SG&A % of Revenue | B9: ='Operating Model'!F10 -> 0.15 | C9: =B9+0.3% -> 0.153 | D9: 0.152 | E9: 0.151 | F9: 0.15
A10: EBITDA | B10: ='Operating Model'!F11 -> 2336.727 | C10: =C4*(C8-C9) -> 2251.9533 | D10: =D4*(D8-D9) -> 2423.7542 | E10: =E4*(E8-E9) -> 2603.4764 | F10: =F4*(F8-F9) -> 2788.3323
A11: EBITDA Margin % | B11: ='Operating Model'!F12 -> 0.291 | C11: =C10/C4 -> 0.283 | D11: =D10/D4 -> 0.286 | E11: =E10/E4 -> 0.289 | F11: =F10/F4 -> 0.292
A12: Operating Income (EBIT) | B12: ='Operating Model'!F15 -> 1847.2495 | C12: =C10-'Operating Model'!F13 -> 1762.4758 | D12: =D10-(D4*6.1%) -> 1906.7997 | E12: =E10-(E4*6.1%) -> 2053.9537 | F12: =F10-(F4*6.1%) -> 2205.8382
A13: Net Income | B13: ='P & L'!F16 -> 1232.2512 | C13: =('Budget & Reforecast'!C12-'P & L'!F13)*(1-25.5%) -> 1169.0948 | D13: =('Budget & Reforecast'!D12-'P & L'!G13)*(1-25.5%) -> 1269.4186 | E13: =('Budget & Reforecast'!E12-'P & L'!H13)*(1-25.5%) -> 1371.491 | F13: =('Budget & Reforecast'!F12-'P & L'!I13)*(1-25.5%) -> 1476.7098
A14: Net Profit Margin % | B14: ='P & L'!F17 -> 0.15345614 | C14: =C13/C4 -> 0.14691861 | D14: =D13/D4 -> 0.14978983 | E14: =E13/E4 -> 0.15224294 | F14: =F13/F4 -> 0.15464414
A16: Metrics | B16: Variance
A17: Revenue | B17: =C4-B4 -> -72.55754
A18: Revenue Variance % | B18: =B17/B4 -> -0.00903582
A19: EBITDA | B19: =C10-B10 -> -84.7737
A20: EBITDA Variance % | B20: =B19/B10 -> -0.036278821
A21: Net Income | B21: =C13-B13 -> -63.156407
A22: Net Profit Variance % | B22: =B21/B13 -> -0.051252866

Sheet Variance & PVM
A1: DOLLARAMA INC. | Variance & PVM CAD in millions
A3: Product Category | B3: Budget Units (M) | C3: Budget Price (CAD) | D3: Reforecast Units (M) | E3: Reforecast Price (CAD) | F3: Budget Revenue (CAD M) | G3: Reforecast Revenue (CAD M) | H3: FY2027 Budget Mix | I3: FY2027 Reforecast Mix
A4: Consumables | B4: =F4/C4 -> 983.67372 | C4: 4 | D4: =G4/E4 -> 984.8307 | E4: =C4*(1+1%) -> 4.04 | F4: ='Budget & Reforecast'!$B$4*'Variance & PVM'!H4 -> 3934.6949 | G4: ='Budget & Reforecast'!$C$4*'Variance & PVM'!I4 -> 3978.716 | H4: 0.49 | I4: 0.5
A5: General Merchandise | B5: =F5/C5 -> 678.08801 | C5: 4.5 | D5: =G5/E5 -> 647.79975 | E5: =C5*(1+1%) -> 4.545 | F5: ='Budget & Reforecast'!$B$4*'Variance & PVM'!H5 -> 3051.396 | G5: ='Budget & Reforecast'!$C$4*'Variance & PVM'!I5 -> 2944.2499 | H5: 0.38 | I5: 0.37
A6: Seasonal Products | B6: =F6/C6 -> 298.25676 | C6: 3.5 | D6: =G6/E6 -> 292.63541 | E6: =C6*(1+1%) -> 3.535 | F6: ='Budget & Reforecast'!$B$4*'Variance & PVM'!H6 -> 1043.8986 | G6: ='Budget & Reforecast'!$C$4*'Variance & PVM'!I6 -> 1034.4662 | H6: 0.13 | I6: 0.13
A7: TOTAL | B7: =SUM(B4:B6) -> 1960.0185 | C7: =SUM(C4:C6) -> 12 | D7: =SUM(D4:D6) -> 1925.2659 | E7: =SUM(E4:E6) -> 12.12 | F7: ='Budget & Reforecast'!$B$4*'Variance & PVM'!H7 -> 8029.9896 | G7: ='Budget & Reforecast'!$C$4*'Variance & PVM'!I7 -> 7957.432 | H7: 1 | I7: 1
A9: PRICE–VOLUME–MIX BRIDGE | D9: MANAGEMENT INSIGHTS
A10: Budget Revenue | B10: ='Budget & Reforecast'!B4 -> 8029.9896 | D10: Revenue Variance | E10: -72.558M (-0.90%) vs. budget
A11: Price Impact | B11: {=SUMPRODUCT(E4:E6-C4:C6,D4:D6)} -> 78.786456 | D11: EBITDA Variance | E11: -84.774M (-3.63%) vs. budget
A12: Volume Impact | B12: =(D7-B7)*(F7/B7) -> -142.37789 | D12: Cost Pressure | E12: Higher COGS and SG&A rates reduced profitability
A13: Mix Impact | B13: =SUMPRODUCT(D4:D6,C4:C6)-D7*(F7/B7) -> -8.9661062 | D13: PVM Analysis | E13: Illustrative price, volume, and mix assumptions
A14: Reforecast Revenue | B14: =B10+B11+B12+B13 -> 7957.432 | D14: Management Priority | E14: Protect gross margins and improve cost efficiency
A15: PVM Reconciliation Check | B15: =B14-G7 -> 0
A17: EBITDA VARIANCE BRIDGE
A18: Budget EBITDA | B18: ='Budget & Reforecast'!B10 -> 2336.727
A19: Revenue Impact | B19: =('Budget & Reforecast'!C4-'Budget & Reforecast'!B4)*'Budget & Reforecast'!B11 -> -21.114244
A20: COGS Rate Impact | B20: =-('Budget & Reforecast'!C7-'Budget & Reforecast'!B7)*'Budget & Reforecast'!C4 -> -39.78716
A21: SG&A Rate Impact | B21: =-('Budget & Reforecast'!C9-'Budget & Reforecast'!B9)*'Budget & Reforecast'!C4 -> -23.872296
A22: Reforecast EBITDA | B22: =SUM(B18:B21) -> 2251.9533
A23: EBITDA Reconciliation Check | B23: =B22-'Budget & Reforecast'!C10 -> 0

Sheet Scenario & Sensitivity 
A1: DOLLARAMA — SCENARIO & SENSITIVITY ANALYSIS CAD in millions | FY2027E–FY2030E
B3: 1 | C3: 2 | D3: 3
A4: SCENARIO ASSUMPTIONS | B4: Best Case | C4: Base Case | D4: Worst Case
A5: Annual Revenue Growth Adjustment | B5: 0.02 | C5: 0 | D5: -0.02
A6: COGS Rate Adjustment | B6: -0.005 | C6: 0 | D6: 0.005
A7: SG&A Rate Adjustment | B7: -0.003 | C7: 0 | D7: 0.003
A8: Tax Rate | B8: 0.255 | C8: 0.255 | D8: 0.255
A10: Choose Scenario | B10: 3
A12: Scenario | B12: FY2027E | C12: FY2028E | D12: FY2029E | E12: FY2030E | G12: Best | H12: =B12 -> FY2027E | I12: =C12 -> FY2028E | J12: =D12 -> FY2029E | K12: =E12 -> FY2030E
A13: Revenue | B13: =CHOOSE($B$10,H13,H17,H21) -> 7798.2834 | C13: =CHOOSE($B$10,I13,I17,I21) -> 8305.1718 | D13: =CHOOSE($B$10,J13,J17,J21) -> 8828.3976 | E13: =CHOOSE($B$10,K13,K17,K21) -> 9358.1015 | G13: Revenue | H13: =H17*(1+$B$5) -> 8116.5807 | I13: =I17*(1+$B$5) -> 8644.1584 | J13: =J17*(1+$B$5) -> 9188.7404 | K13: =K17*(1+$B$5) -> 9740.0648
A14: COGS % | B14: =CHOOSE($B$10,H14,H18,H22) -> 0.569 | C14: =CHOOSE($B$10,I14,I18,I22) -> 0.567 | D14: =CHOOSE($B$10,J14,J18,J22) -> 0.565 | E14: =CHOOSE($B$10,K14,K18,K22) -> 0.563 | G14: COGS % | H14: =H18-0.5% -> 0.559 | I14: =I18-0.5% -> 0.557 | J14: =J18-0.5% -> 0.555 | K14: =K18-0.5% -> 0.553
A15: SG&A % of Revenue | B15: =CHOOSE($B$10,H15,H19,H23) -> 0.156 | C15: =CHOOSE($B$10,I15,I19,I23) -> 0.155 | D15: =CHOOSE($B$10,J15,J19,J23) -> 0.154 | E15: =CHOOSE($B$10,K15,K19,K23) -> 0.153 | G15: SG&A % | H15: =H19-0.3% -> 0.15 | I15: =I19-0.3% -> 0.149 | J15: =J19-0.3% -> 0.148 | K15: =K19-0.3% -> 0.147
A16: COGS | B16: =B13*B14 -> 4437.2232 | C16: =C13*C14 -> 4709.0324 | D16: =D13*D14 -> 4988.0447 | E16: =E13*E14 -> 5268.6111 | G16: Base
A17: Gross Profit | B17: =B13-B16 -> 3361.0601 | C17: =C13-C16 -> 3596.1394 | D17: =D13-D16 -> 3840.353 | E17: =E13-E16 -> 4089.4904 | G17: Revenue | H17: ='Budget & Reforecast'!C4 -> 7957.432 | I17: ='Budget & Reforecast'!D4 -> 8474.6651 | J17: ='Budget & Reforecast'!E4 -> 9008.569 | K17: ='Budget & Reforecast'!F4 -> 9549.0832
A18: SG&A | B18: =B13*B15 -> 1216.5322 | C18: =C13*C15 -> 1287.3016 | D18: =D13*D15 -> 1359.5732 | E18: =E13*E15 -> 1431.7895 | G18: COGS % | H18: ='Budget & Reforecast'!C7 -> 0.564 | I18: ='Budget & Reforecast'!D7 -> 0.562 | J18: ='Budget & Reforecast'!E7 -> 0.56 | K18: ='Budget & Reforecast'!F7 -> 0.558
A19: EBITDA | B19: =B17-B18 -> 2144.5279 | C19: =C17-C18 -> 2308.8378 | D19: =D17-D18 -> 2480.7797 | E19: =E17-E18 -> 2657.7008 | G19: SG&A % | H19: ='Budget & Reforecast'!C9 -> 0.153 | I19: ='Budget & Reforecast'!D9 -> 0.152 | J19: ='Budget & Reforecast'!E9 -> 0.151 | K19: ='Budget & Reforecast'!F9 -> 0.15
A20: EBITDA Margin % | B20: =B19/B13 -> 0.275 | C20: =C19/C13 -> 0.278 | D20: =D19/D13 -> 0.281 | E20: =E19/E13 -> 0.284 | G20: Worst
A21: Operating Income | B21: =B19-('Budget & Reforecast'!C10-'Budget & Reforecast'!C12) -> 1655.0505 | C21: =C19-('Budget & Reforecast'!D10-'Budget & Reforecast'!D12) -> 1791.8832 | D21: =D19-('Budget & Reforecast'!E10-'Budget & Reforecast'!E12) -> 1931.257 | E21: =E19-('Budget & Reforecast'!F10-'Budget & Reforecast'!F12) -> 2075.2068 | G21: =G17 -> Revenue | H21: =H17*(1+$D$5) -> 7798.2834 | I21: =I17*(1+$D$5) -> 8305.1718 | J21: =J17*(1+$D$5) -> 8828.3976 | K21: =K17*(1+$D$5) -> 9358.1015
A22: Net Income | B22: ='Budget & Reforecast'!C13+('Scenario & Sensitivity '!B21-'Budget & Reforecast'!C12)*(1-'Scenario & Sensitivity '!$B$8) -> 1089.0629 | C22: ='Budget & Reforecast'!D13+('Scenario & Sensitivity '!C21-'Budget & Reforecast'!D12)*(1-'Scenario & Sensitivity '!$B$8) -> 1183.8059 | D22: ='Budget & Reforecast'!E13+('Scenario & Sensitivity '!D21-'Budget & Reforecast'!E12)*(1-'Scenario & Sensitivity '!$B$8) -> 1280.082 | E22: ='Budget & Reforecast'!F13+('Scenario & Sensitivity '!E21-'Budget & Reforecast'!F12)*(1-'Scenario & Sensitivity '!$B$8) -> 1379.3893 | G22: =G18 -> COGS % | H22: =H18+$D$6 -> 0.569 | I22: =I18+$D$6 -> 0.567 | J22: =J18+$D$6 -> 0.565 | K22: =K18+$D$6 -> 0.563
A23: Net Profit Margin | B23: =B22/B13 -> 0.13965419 | C23: =C22/C13 -> 0.14253839 | D23: =D22/D13 -> 0.14499596 | E23: =E22/E13 -> 0.14740055 | G23: =G19 -> SG&A % | H23: =H19+$D$7 -> 0.156 | I23: =I19+$D$7 -> 0.155 | J23: =J19+$D$7 -> 0.154 | K23: =K19+$D$7 -> 0.153
A26: FY2027 EBITDA SENSITIVITY — CAD MILLIONS
A27: Revenue Change / COGS Change | B27: -0.01 | C27: -0.005 | D27: 0 | E27: 0.005 | F27: 0.01
A28: -0.04 | B28: ='Budget & Reforecast'!$C$4*(1+$A28)*(1-'Budget & Reforecast'!$C$7-B$27-'Budget & Reforecast'!$C$9) -> 2238.2665 | C28: ='Budget & Reforecast'!$C$4*(1+$A28)*(1-'Budget & Reforecast'!$C$7-C$27-'Budget & Reforecast'!$C$9) -> 2200.0708 | D28: ='Budget & Reforecast'!$C$4*(1+$A28)*(1-'Budget & Reforecast'!$C$7-D$27-'Budget & Reforecast'!$C$9) -> 2161.8751 | E28: ='Budget & Reforecast'!$C$4*(1+$A28)*(1-'Budget & Reforecast'!$C$7-E$27-'Budget & Reforecast'!$C$9) -> 2123.6795 | F28: ='Budget & Reforecast'!$C$4*(1+$A28)*(1-'Budget & Reforecast'!$C$7-F$27-'Budget & Reforecast'!$C$9) -> 2085.4838
A29: -0.02 | B29: ='Budget & Reforecast'!$C$4*(1+$A29)*(1-'Budget & Reforecast'!$C$7-B$27-'Budget & Reforecast'!$C$9) -> 2284.897 | C29: ='Budget & Reforecast'!$C$4*(1+$A29)*(1-'Budget & Reforecast'!$C$7-C$27-'Budget & Reforecast'!$C$9) -> 2245.9056 | D29: ='Budget & Reforecast'!$C$4*(1+$A29)*(1-'Budget & Reforecast'!$C$7-D$27-'Budget & Reforecast'!$C$9) -> 2206.9142 | E29: ='Budget & Reforecast'!$C$4*(1+$A29)*(1-'Budget & Reforecast'!$C$7-E$27-'Budget & Reforecast'!$C$9) -> 2167.9228 | F29: ='Budget & Reforecast'!$C$4*(1+$A29)*(1-'Budget & Reforecast'!$C$7-F$27-'Budget & Reforecast'!$C$9) -> 2128.9314
A30: 0 | B30: ='Budget & Reforecast'!$C$4*(1+$A30)*(1-'Budget & Reforecast'!$C$7-B$27-'Budget & Reforecast'!$C$9) -> 2331.5276 | C30: ='Budget & Reforecast'!$C$4*(1+$A30)*(1-'Budget & Reforecast'!$C$7-C$27-'Budget & Reforecast'!$C$9) -> 2291.7404 | D30: ='Budget & Reforecast'!$C$4*(1+$A30)*(1-'Budget & Reforecast'!$C$7-D$27-'Budget & Reforecast'!$C$9) -> 2251.9533 | E30: ='Budget & Reforecast'!$C$4*(1+$A30)*(1-'Budget & Reforecast'!$C$7-E$27-'Budget & Reforecast'!$C$9) -> 2212.1661 | F30: ='Budget & Reforecast'!$C$4*(1+$A30)*(1-'Budget & Reforecast'!$C$7-F$27-'Budget & Reforecast'!$C$9) -> 2172.3789
A31: 0.02 | B31: ='Budget & Reforecast'!$C$4*(1+$A31)*(1-'Budget & Reforecast'!$C$7-B$27-'Budget & Reforecast'!$C$9) -> 2378.1581 | C31: ='Budget & Reforecast'!$C$4*(1+$A31)*(1-'Budget & Reforecast'!$C$7-C$27-'Budget & Reforecast'!$C$9) -> 2337.5752 | D31: ='Budget & Reforecast'!$C$4*(1+$A31)*(1-'Budget & Reforecast'!$C$7-D$27-'Budget & Reforecast'!$C$9) -> 2296.9923 | E31: ='Budget & Reforecast'!$C$4*(1+$A31)*(1-'Budget & Reforecast'!$C$7-E$27-'Budget & Reforecast'!$C$9) -> 2256.4094 | F31: ='Budget & Reforecast'!$C$4*(1+$A31)*(1-'Budget & Reforecast'!$C$7-F$27-'Budget & Reforecast'!$C$9) -> 2215.8265
A32: 0.04 | B32: ='Budget & Reforecast'!$C$4*(1+$A32)*(1-'Budget & Reforecast'!$C$7-B$27-'Budget & Reforecast'!$C$9) -> 2424.7887 | C32: ='Budget & Reforecast'!$C$4*(1+$A32)*(1-'Budget & Reforecast'!$C$7-C$27-'Budget & Reforecast'!$C$9) -> 2383.41 | D32: ='Budget & Reforecast'!$C$4*(1+$A32)*(1-'Budget & Reforecast'!$C$7-D$27-'Budget & Reforecast'!$C$9) -> 2342.0314 | E32: ='Budget & Reforecast'!$C$4*(1+$A32)*(1-'Budget & Reforecast'!$C$7-E$27-'Budget & Reforecast'!$C$9) -> 2300.6527 | F32: ='Budget & Reforecast'!$C$4*(1+$A32)*(1-'Budget & Reforecast'!$C$7-F$27-'Budget & Reforecast'!$C$9) -> 2259.2741
A34: FY2027 NET INCOME SENSITIVITY — CAD MILLIONS
A35: Revenue Change / SG&A Change | B35: -0.01 | C35: -0.005 | D35: 0 | E35: 0.005 | F35: 0.01
A36: -0.04 | B36: ='Budget & Reforecast'!$C$13+('Budget & Reforecast'!$C$4*(1+$A36)*(1-'Budget & Reforecast'!$C$7-'Budget & Reforecast'!$C$9-B$35)-'Budget & Reforecast'!$C$10)*(1-25.5%) -> 1158.8982 | C36: ='Budget & Reforecast'!$C$13+('Budget & Reforecast'!$C$4*(1+$A36)*(1-'Budget & Reforecast'!$C$7-'Budget & Reforecast'!$C$9-C$35)-'Budget & Reforecast'!$C$10)*(1-25.5%) -> 1130.4424 | D36: ='Budget & Reforecast'!$C$13+('Budget & Reforecast'!$C$4*(1+$A36)*(1-'Budget & Reforecast'!$C$7-'Budget & Reforecast'!$C$9-D$35)-'Budget & Reforecast'!$C$10)*(1-25.5%) -> 1101.9866 | E36: ='Budget & Reforecast'!$C$13+('Budget & Reforecast'!$C$4*(1+$A36)*(1-'Budget & Reforecast'!$C$7-'Budget & Reforecast'!$C$9-E$35)-'Budget & Reforecast'!$C$10)*(1-25.5%) -> 1073.5308 | F36: ='Budget & Reforecast'!$C$13+('Budget & Reforecast'!$C$4*(1+$A36)*(1-'Budget & Reforecast'!$C$7-'Budget & Reforecast'!$C$9-F$35)-'Budget & Reforecast'!$C$10)*(1-25.5%) -> 1045.0751
A37: -0.02 | B37: ='Budget & Reforecast'!$C$13+('Budget & Reforecast'!$C$4*(1+$A37)*(1-'Budget & Reforecast'!$C$7-'Budget & Reforecast'!$C$9-B$35)-'Budget & Reforecast'!$C$10)*(1-25.5%) -> 1193.6379 | C37: ='Budget & Reforecast'!$C$13+('Budget & Reforecast'!$C$4*(1+$A37)*(1-'Budget & Reforecast'!$C$7-'Budget & Reforecast'!$C$9-C$35)-'Budget & Reforecast'!$C$10)*(1-25.5%) -> 1164.5893 | D37: ='Budget & Reforecast'!$C$13+('Budget & Reforecast'!$C$4*(1+$A37)*(1-'Budget & Reforecast'!$C$7-'Budget & Reforecast'!$C$9-D$35)-'Budget & Reforecast'!$C$10)*(1-25.5%) -> 1135.5407 | E37: ='Budget & Reforecast'!$C$13+('Budget & Reforecast'!$C$4*(1+$A37)*(1-'Budget & Reforecast'!$C$7-'Budget & Reforecast'!$C$9-E$35)-'Budget & Reforecast'!$C$10)*(1-25.5%) -> 1106.4921 | F37: ='Budget & Reforecast'!$C$13+('Budget & Reforecast'!$C$4*(1+$A37)*(1-'Budget & Reforecast'!$C$7-'Budget & Reforecast'!$C$9-F$35)-'Budget & Reforecast'!$C$10)*(1-25.5%) -> 1077.4435
A38: 0 | B38: ='Budget & Reforecast'!$C$13+('Budget & Reforecast'!$C$4*(1+$A38)*(1-'Budget & Reforecast'!$C$7-'Budget & Reforecast'!$C$9-B$35)-'Budget & Reforecast'!$C$10)*(1-25.5%) -> 1228.3777 | C38: ='Budget & Reforecast'!$C$13+('Budget & Reforecast'!$C$4*(1+$A38)*(1-'Budget & Reforecast'!$C$7-'Budget & Reforecast'!$C$9-C$35)-'Budget & Reforecast'!$C$10)*(1-25.5%) -> 1198.7362 | D38: ='Budget & Reforecast'!$C$13+('Budget & Reforecast'!$C$4*(1+$A38)*(1-'Budget & Reforecast'!$C$7-'Budget & Reforecast'!$C$9-D$35)-'Budget & Reforecast'!$C$10)*(1-25.5%) -> 1169.0948 | E38: ='Budget & Reforecast'!$C$13+('Budget & Reforecast'!$C$4*(1+$A38)*(1-'Budget & Reforecast'!$C$7-'Budget & Reforecast'!$C$9-E$35)-'Budget & Reforecast'!$C$10)*(1-25.5%) -> 1139.4534 | F38: ='Budget & Reforecast'!$C$13+('Budget & Reforecast'!$C$4*(1+$A38)*(1-'Budget & Reforecast'!$C$7-'Budget & Reforecast'!$C$9-F$35)-'Budget & Reforecast'!$C$10)*(1-25.5%) -> 1109.8119
A39: 0.02 | B39: ='Budget & Reforecast'!$C$13+('Budget & Reforecast'!$C$4*(1+$A39)*(1-'Budget & Reforecast'!$C$7-'Budget & Reforecast'!$C$9-B$35)-'Budget & Reforecast'!$C$10)*(1-25.5%) -> 1263.1174 | C39: ='Budget & Reforecast'!$C$13+('Budget & Reforecast'!$C$4*(1+$A39)*(1-'Budget & Reforecast'!$C$7-'Budget & Reforecast'!$C$9-C$35)-'Budget & Reforecast'!$C$10)*(1-25.5%) -> 1232.8832 | D39: ='Budget & Reforecast'!$C$13+('Budget & Reforecast'!$C$4*(1+$A39)*(1-'Budget & Reforecast'!$C$7-'Budget & Reforecast'!$C$9-D$35)-'Budget & Reforecast'!$C$10)*(1-25.5%) -> 1202.6489 | E39: ='Budget & Reforecast'!$C$13+('Budget & Reforecast'!$C$4*(1+$A39)*(1-'Budget & Reforecast'!$C$7-'Budget & Reforecast'!$C$9-E$35)-'Budget & Reforecast'!$C$10)*(1-25.5%) -> 1172.4147 | F39: ='Budget & Reforecast'!$C$13+('Budget & Reforecast'!$C$4*(1+$A39)*(1-'Budget & Reforecast'!$C$7-'Budget & Reforecast'!$C$9-F$35)-'Budget & Reforecast'!$C$10)*(1-25.5%) -> 1142.1804
A40: 0.04 | B40: ='Budget & Reforecast'!$C$13+('Budget & Reforecast'!$C$4*(1+$A40)*(1-'Budget & Reforecast'!$C$7-'Budget & Reforecast'!$C$9-B$35)-'Budget & Reforecast'!$C$10)*(1-25.5%) -> 1297.8572 | C40: ='Budget & Reforecast'!$C$13+('Budget & Reforecast'!$C$4*(1+$A40)*(1-'Budget & Reforecast'!$C$7-'Budget & Reforecast'!$C$9-C$35)-'Budget & Reforecast'!$C$10)*(1-25.5%) -> 1267.0301 | D40: ='Budget & Reforecast'!$C$13+('Budget & Reforecast'!$C$4*(1+$A40)*(1-'Budget & Reforecast'!$C$7-'Budget & Reforecast'!$C$9-D$35)-'Budget & Reforecast'!$C$10)*(1-25.5%) -> 1236.203 | E40: ='Budget & Reforecast'!$C$13+('Budget & Reforecast'!$C$4*(1+$A40)*(1-'Budget & Reforecast'!$C$7-'Budget & Reforecast'!$C$9-E$35)-'Budget & Reforecast'!$C$10)*(1-25.5%) -> 1205.3759 | F40: ='Budget & Reforecast'!$C$13+('Budget & Reforecast'!$C$4*(1+$A40)*(1-'Budget & Reforecast'!$C$7-'Budget & Reforecast'!$C$9-F$35)-'Budget & Reforecast'!$C$10)*(1-25.5%) -> 1174.5488

Sheet DCF Valuation
A1: DOLLARAMA — DCF VALUATION (CAD MILLIONS)
